File: test_thin.csv
Time(sec),Displacement(mm),Load(N),strain(mm/mm)
0,0.03187,441.67042,0.00013
0.1,0.03118,463.2175,0.00012
0.25,0.0336,504.52352,0.00013
0.4,0.03719,542.73009,0.00015
0.55,0.0382,572.11518,0.00015
0.7,0.03889,572.3536,0.00016
0.85,0.04098,623.79241,0.00016
1,0.04303,647.39585,0.00017
1.15,0.04423,700.20556,0.00018
1.3,0.04733,745.5945,0.00019
1.45,0.05104,769.76418,0.0002
1.6,0.04934,799.4771,0.0002
1.75,0.05146,834.37562,0.00021
1.9,0.0527,873.80409,0.00021
2.05,0.05659,890.34438,0.00023
2.2,0.05872,926.22638,0.00023
2.35,0.06162,962.82363,0.00025
2.5,0.06202,1013.10015,0.00025
2.65,0.06461,1042.63425,0.00026
2.8,0.06619,1090.94381,0.00026
2.95,0.06679,1114.96449,0.00027
3.1,0.07073,1127.33245,0.00028
3.25,0.07178,1174.06249,0.00029
3.4,0.07479,1208.42457,0.0003
3.55,0.07697,1243.68072,0.00031
3.7,0.07784,1275.47979,0.00031
3.85,0.07932,1313.68637,0.00032
4,0.08146,1363.18803,0.00033
4.15,0.08249,1409.59024,0.00033
4.3,0.08722,1426.01132,0.00035
4.45,0.08565,1434.53479,0.00034
4.6,0.08736,1475.51298,0.00035
4.75,0.09148,1534.93881,0.00037
4.9,0.09068,1556.5455,0.00036
5.05,0.09264,1584.8279,0.00037
5.2,0.09583,1629.08435,0.00038
5.35,0.09538,1692.44409,0.00038
5.5,0.10009,1704.69284,0.0004
5.65,0.10338,1760.72121,0.00041
5.8,0.10338,1793.05673,0.00041
5.95,0.10506,1797.64628,0.00042
6.1,0.10622,1857.04231,0.00042
6.25,0.10929,1877.18868,0.00044
6.4,0.10994,1921.80276,0.00044
6.55,0.11245,1960.75439,0.00045
6.7,0.11495,1986.29498,0.00046
6.85,0.11775,2040.3266,0.00047
7,0.11694,2064.46648,0.00047
7.15,0.12039,2110.12363,0.00048
7.3,0.12064,2147.16792,0.00048
7.45,0.12417,2184.59964,0.0005
7.6,0.12593,2219.79618,0.0005
7.75,0.12771,2249.44949,0.00051
7.9,0.12887,2298.17629,0.00052
8.05,0.1309,2322.28637,0.00052
8.2,0.13317,2365.0825,0.00053
8.35,0.1358,2404.71959,0.00054
8.5,0.13814,2460.83736,0.00055
8.65,0.13862,2504.14014,0.00055
8.8,0.14042,2530.6046,0.00056
8.95,0.14191,2590.14964,0.00057
9.1,0.14448,2620.48841,0.00058
9.25,0.14598,2669.33441,0.00058
9.4,0.14735,2682.53684,0.00059
9.55,0.15125,2710.78944,0.0006
9.7,0.15136,2752.03586,0.00061
9.85,0.15315,2781.33154,0.00061
10,0.15602,2820.37258,0.00062
10.15,0.15879,2871.27495,0.00064
10.3,0.15955,2889.48417,0.00064
10.45,0.16226,2939.73088,0.00065
10.6,0.16378,2978.53351,0.00066
10.75,0.16423,3047.7047,0.00066
10.9,0.168,3078.19247,0.00067
11.05,0.16993,3110.08096,0.00068
11.2,0.17102,3124.05825,0.00068
11.35,0.17469,3188.9677,0.0007
11.5,0.17351,3225.14772,0.00069
11.65,0.17638,3252.35724,0.00071
11.8,0.17791,3275.09642,0.00071
11.95,0.18035,3320.90259,0.00072
12.1,0.18032,3363.22188,0.00072
12.25,0.18452,3400.26617,0.00074
12.4,0.18642,3442.52586,0.00075
12.55,0.1869,3478.9741,0.00075
12.7,0.19078,3550.7679,0.00076
12.85,0.19087,3555.68528,0.00076
13,0.19493,3600.35896,0.00078
13.15,0.19565,3629.1182,0.00078
13.3,0.19811,3674.62635,0.00079
13.45,0.19608,3723.35315,0.00078
13.6,0.20087,3746.24133,0.0008
13.75,0.20091,3779.02389,0.0008
13.9,0.20446,3839.19477,0.00082
14.05,0.20975,3873.67606,0.00084
14.2,0.20801,3909.20043,0.00083
14.35,0.20978,3953.00984,0.00084
14.5,0.21123,3987.0441,0.00084
14.65,0.2124,4027.12822,0.00085
14.8,0.21361,4058.71868,0.00085
14.95,0.21551,4089.38527,0.00086
15.1,0.21918,4151.07608,0.00088
15.25,0.21985,4180.43137,0.00088
15.4,0.22447,4198.43197,0.0009
15.55,0.22375,4253.9537,0.00089
15.7,0.22548,4303.03812,0.0009
15.85,0.22764,4353.22523,0.00091
16,0.23163,4389.67347,0.00093
16.15,0.23218,4418.84995,0.00093
16.3,0.23443,4480.30233,0.00094
16.45,0.23892,4525.03562,0.00096
16.6,0.23671,4530.99608,0.00095
16.75,0.24245,4612.23722,0.00097
16.9,0.2438,4624.09854,0.00098
17.05,0.24442,4653.30482,0.00098
17.2,0.24273,4704.50521,0.00097
17.35,0.24625,4735.55923,0.00099
17.5,0.24942,4777.40169,0.001
17.65,0.25166,4828.8703,0.00101
17.8,0.25259,4865.05032,0.00101
17.95,0.25371,4908.35309,0.00101
18.1,0.25953,4932.58238,0.00104
18.25,0.25952,4944.77153,0.00104
18.4,0.26067,5009.44257,0.00104
18.55,0.26065,5039.84094,0.00104
18.7,0.26193,5084.66363,0.00105
18.85,0.2667,5136.34086,0.00107
19,0.26549,5176.723,0.00106
19.15,0.27074,5222.73779,0.00108
19.3,0.27263,5254.59647,0.00109
19.45,0.27314,5303.7107,0.00109
19.6,0.27677,5330.02615,0.00111
19.75,0.27612,5375.29588,0.0011
19.9,0.28137,5410.99906,0.00113
20.05,0.27926,5450.57654,0.00112
20.2,0.28228,5496.29331,0.00113
20.35,0.28499,5523.94986,0.00114
20.5,0.28703,5566.14995,0.00115
20.65,0.28926,5616.03904,0.00116
20.8,0.29125,5631.20842,0.00117
20.95,0.29187,5713.64164,0.00117
21.1,0.29398,5732.50651,0.00118
21.25,0.29664,5779.71339,0.00119
21.4,0.2976,5804.92616,0.00119
21.55,0.30122,5828.5594,0.0012
21.7,0.30146,5870.22305,0.00121
21.85,0.30361,5925.35734,0.00121
22,0.3063,5969.94162,0.00123
22.15,0.30713,6018.96644,0.00123
22.3,0.31223,6052.94108,0.00125
22.45,0.31081,6088.91249,0.00124
22.6,0.31488,6099.90954,0.00126
22.75,0.3125,6158.79893,0.00125
22.9,0.31862,6202.63815,0.00127
23.05,0.31936,6237.44726,0.00128
23.2,0.32055,6281.43549,0.00128
23.35,0.32305,6346.01712,0.00129
23.5,0.32451,6358.47449,0.0013
23.65,0.32613,6405.32374,0.0013
23.8,0.32598,6435.90093,0.0013
23.95,0.33048,6487.48875,0.00132
24.1,0.33292,6517.11226,0.00133
24.25,0.3343,6559.37195,0.00134
24.4,0.33597,6595.67118,0.00134
24.55,0.33973,6654.14333,0.00136
24.7,0.33991,6679.17728,0.00136
24.85,0.34153,6726.65238,0.00137
25,0.34297,6774.57452,0.00137
25.15,0.34524,6820.35089,0.00138
25.3,0.34567,6856.29249,0.00138
25.45,0.34817,6887.10809,0.00139
25.6,0.35008,6913.24472,0.0014
25.75,0.35281,6972.52154,0.00141
25.9,0.35489,7004.11201,0.00142
26.05,0.35748,7059.33571,0.00143
26.2,0.35833,7082.58152,0.00143
26.35,0.36111,7118.34431,0.00144
26.5,0.36205,7170.08114,0.00145
26.65,0.36497,7192.96932,0.00146
26.8,0.36715,7232.66602,0.00147
26.95,0.3677,7270.48516,0.00147
27.1,0.36846,7304.45981,0.00147
27.25,0.37254,7360.30936,0.00149
27.4,0.37253,7409.69181,0.00149
27.55,0.37399,7441.72931,0.0015
27.7,0.3757,7458.86564,0.0015
27.85,0.37918,7524.07312,0.00152
28,0.38058,7550.06075,0.00152
28.15,0.38341,7609.7846,0.00153
28.3,0.38379,7640.86843,0.00154
28.45,0.38771,7668.40577,0.00155
28.6,0.38984,7725.44742,0.00156
28.75,0.38992,7757.84254,0.00156
28.9,0.39122,7801.74136,0.00156
29.05,0.39521,7816.64252,0.00158
29.2,0.39579,7856.90546,0.00158
29.35,0.3979,7891.29734,0.00159
29.5,0.3972,7923.18583,0.00159
29.65,0.40182,7992.53583,0.00161
29.8,0.40051,8029.25229,0.0016
29.95,0.40577,8048.6834,0.00162
30.1,0.40677,8073.44913,0.00163
30.25,0.40763,8123.0104,0.00163
30.4,0.40967,8155.52473,0.00164
30.55,0.41077,8218.64605,0.00164
30.7,0.41548,8257.12085,0.00166
30.85,0.4161,8303.76148,0.00166
31,0.41999,8336.69305,0.00168
31.15,0.42005,8384.8238,0.00168
31.3,0.42188,8418.38121,0.00169
31.45,0.42458,8454.65064,0.0017
31.6,0.42661,8479.68459,0.00171
31.75,0.42765,8531.21281,0.00171
31.9,0.42986,8585.09541,0.00172
32.05,0.42973,8620.02373,0.00172
32.2,0.43417,8657.63426,0.00174
32.35,0.43352,8646.10076,0.00173
32.5,0.43744,8718.40119,0.00175
32.65,0.43967,8762.62784,0.00176
32.8,0.44086,8801.9371,0.00176
32.95,0.44184,8841.18676,0.00177
33.1,0.44374,8877.45619,0.00177
33.25,0.44852,8923.91801,0.00179
33.4,0.45039,8945.88232,0.0018
33.55,0.45075,8980.12519,0.0018
33.7,0.454,9039.253,0.00182
33.85,0.4537,9042.65046,0.00181
34,0.45619,9130.15008,0.00182
34.15,0.45817,9135.66351,0.00183
34.3,0.45967,9193.62903,0.00184
34.45,0.46207,9246.08111,0.00185
34.6,0.46476,9272.00913,0.00186
34.75,0.46474,9301.99027,0.00186
34.9,0.46635,9349.76339,0.00187
35.05,0.46864,9375.98944,0.00187
35.2,0.47008,9399.44386,0.00188
35.35,0.47075,9434.5808,0.00188
35.5,0.47639,9513.58676,0.00191
35.65,0.47702,9542.97185,0.00191
35.8,0.47725,9556.97894,0.00191
35.95,0.48234,9598.58298,0.00193
36.1,0.48084,9620.04066,0.00192
36.25,0.48196,9689.83769,0.00193
36.4,0.48678,9732.2464,0.00195
36.55,0.48789,9744.55476,0.00195
36.7,0.48805,9776.62206,0.00195
36.85,0.49151,9836.28631,0.00197
37,0.4914,9880.12552,0.00197
37.15,0.49369,9926.0509,0.00197
37.3,0.49668,9950.04177,0.00199
37.45,0.50029,9971.91668,0.002
37.6,0.50214,10012.77566,0.00201
37.75,0.5013,10071.27762,0.00201
37.9,0.50408,10111.86838,0.00202
38.05,0.50662,10140.86604,0.00203
38.2,0.50808,10184.73506,0.00203
38.35,0.51123,10197.46065,0.00204
38.5,0.51118,10237.60438,0.00204
38.65,0.51339,10294.02018,0.00205
38.8,0.51523,10337.17394,0.00206
38.95,0.51921,10369.42005,0.00208
39.1,0.52023,10404.08015,0.00208
39.25,0.52193,10449.88632,0.00209
39.4,0.52383,10502.57683,0.0021
39.55,0.52591,10514.97459,0.0021
39.7,0.52772,10552.73414,0.00211
39.85,0.52958,10569.57245,0.00212
40,0.53209,10634.03487,0.00213
40.15,0.53439,10679.96025,0.00214
40.3,0.53492,10702.93784,0.00214
40.45,0.53892,10734.20048,0.00216
40.6,0.53944,10782.36103,0.00216
40.75,0.5393,10814.51774,0.00216
40.9,0.54259,10874.71843,0.00217
41.05,0.54356,10879.69542,0.00217
41.2,0.54439,10931.78988,0.00218
41.35,0.54709,10990.47065,0.00219
41.5,0.55079,11018.57424,0.0022
41.65,0.5511,11053.83039,0.0022
41.8,0.55438,11070.22166,0.00222
41.95,0.55612,11118.05439,0.00222
42.1,0.55839,11132.47871,0.00223
42.25,0.55785,11221.25983,0.00223
42.4,0.55933,11217.62395,0.00224
42.55,0.5628,11277.55642,0.00225
42.7,0.56326,11284.20234,0.00225
42.85,0.56807,11334.80668,0.00227
43,0.5678,11391.43109,0.00227
43.15,0.57028,11407.61375,0.00228
43.3,0.57317,11431.60462,0.00229
43.45,0.57532,11506.82569,0.0023
43.6,0.57474,11518.09096,0.0023
43.75,0.57847,11550.33708,0.00231
43.9,0.57879,11570.87088,0.00232
44.05,0.58358,11616.28962,0.00233
44.2,0.58178,11663.04946,0.00233
44.35,0.58749,11703.72963,0.00235
44.5,0.58875,11736.36317,0.00236
44.65,0.58739,11758.32748,0.00235
44.8,0.59055,11816.41221,0.00236
44.95,0.59311,11856.28772,0.00237
45.1,0.59506,11868.47687,0.00238
45.25,0.59642,11921.31639,0.00239
45.4,0.59773,11941.46276,0.00239
45.55,0.60118,11976.12286,0.0024
45.7,0.60225,12019.30642,0.00241
45.85,0.60425,12047.3206,0.00242
46,0.60424,12092.76915,0.00242
46.15,0.60937,12123.07811,0.00244
46.3,0.60841,12154.48976,0.00243
46.45,0.61166,12162.50658,0.00245
46.6,0.61408,12212.69369,0.00246
46.75,0.61472,12258.58927,0.00246
46.9,0.61817,12289.97111,0.00247
47.05,0.61914,12306.69022,0.00248
47.2,0.62184,12348.08564,0.00249
47.35,0.62334,12375.35477,0.00249
47.5,0.62366,12418.44893,0.00249
47.65,0.62528,12450.96326,0.0025
47.8,0.62806,12491.70303,0.00251
47.95,0.62986,12508.72016,0.00252
48.1,0.63192,12540.96627,0.00253
48.25,0.63238,12602.71668,0.00253
48.4,0.63682,12616.00852,0.00255
48.55,0.63766,12655.31778,0.00255
48.7,0.6404,12669.74211,0.00256
48.85,0.64014,12717.48543,0.00256
49,0.64284,12749.85075,0.00257
49.15,0.64521,12757.86757,0.00258
49.3,0.64642,12775.36154,0.00259
49.45,0.64954,12836.75432,0.0026
49.6,0.64858,12890.16008,0.00259
49.75,0.65095,12895.61391,0.0026
49.9,0.65275,12909.23357,0.00261
50.05,0.65679,12919.27695,0.00263
50.2,0.6579,12984.66325,0.00263
50.35,0.6604,13009.96542,0.00264
50.5,0.6593,13018.42928,0.00264
50.65,0.66461,13037.8902,0.00266
50.8,0.66421,13064.8613,0.00266
50.95,0.67017,13122.17116,0.00268
51.1,0.66989,13133.82387,0.00268
51.25,0.67407,13169.05022,0.0027
51.4,0.67549,13183.80237,0.0027
51.55,0.67602,13212.29339,0.0027
51.7,0.67573,13212.29339,0.0027
51.85,0.68042,13250.14234,0.00272
52,0.68078,13268.9178,0.00272
52.15,0.68319,13268.67938,0.00273
52.3,0.68542,13314.69417,0.00274
52.45,0.68788,13318.27044,0.00275
52.6,0.68813,13309.74698,0.00275
52.75,0.68997,13325.3336,0.00276
52.9,0.69021,13338.86385,0.00276
53.05,0.69501,13387.11381,0.00278
53.2,0.69619,13416.73732,0.00278
53.35,0.69896,13410.27021,0.0028
53.5,0.69965,13419.00229,0.0028
53.65,0.70342,13459.77187,0.00281
53.8,0.70226,13482.92828,0.00281
53.95,0.70791,13484.26938,0.00283
54.1,0.7097,13503.40247,0.00284
54.25,0.70894,13511.27028,0.00284
54.4,0.71045,13533.65183,0.00284
54.55,0.71377,13552.09947,0.00286
54.7,0.71534,13536.06582,0.00286
54.85,0.71726,13570.04046,0.00287
55,0.71918,13575.70291,0.00288
55.15,0.71958,13628.54242,0.00288
55.3,0.72063,13599.30634,0.00288
55.45,0.72368,13618.97588,0.00289
55.6,0.72697,13630.8372,0.00291
55.75,0.72727,13645.05291,0.00291
55.9,0.7293,13673.45452,0.00292
56.05,0.73154,13665.16948,0.00293
56.2,0.73302,13663.70916,0.00293
56.35,0.73687,13678.87855,0.00295
56.5,0.73919,13714.90955,0.00296
56.65,0.73892,13715.32679,0.00296
56.8,0.74101,13737.3209,0.00296
56.95,0.74253,13731.80747,0.00297
57.1,0.74507,13766.52718,0.00298
57.25,0.74711,13773.73934,0.00299
57.4,0.74967,13790.99488,0.003
57.55,0.74922,13773.76914,0.003
57.7,0.75096,13793.8261,0.003
57.85,0.75483,13805.2702,0.00302
58,0.75322,13800.71044,0.00301
58.15,0.75849,13831.34723,0.00303
58.3,0.75881,13819.99254,0.00304
58.45,0.76176,13825.95301,0.00305
58.6,0.76277,13850.56973,0.00305
58.75,0.76617,13870.7757,0.00306
58.9,0.76589,13847.23186,0.00306
59.05,0.76894,13878.28588,0.00308
59.2,0.77165,13886.03449,0.00309
59.35,0.77347,13907.49216,0.00309
59.5,0.77452,13883.29268,0.0031
59.65,0.77395,13890.53464,0.0031
59.8,0.77821,13892.53139,0.00311
59.95,0.78019,13919.74092,0.00312
60.1,0.78235,13913.92946,0.00313
60.25,0.7834,13907.73058,0.00313
60.4,0.78717,13934.8805,0.00315
60.55,0.78461,13940.57274,0.00314
60.7,0.7894,13949.78166,0.00316
60.85,0.7916,13956.33817,0.00317
61,0.79209,13970.58368,0.00317
61.15,0.79772,13955.35469,0.00319
61.3,0.79662,13975.47126,0.00319
61.45,0.80009,13991.83273,0.0032
61.6,0.80232,13980.32904,0.00321
61.75,0.80349,14008.64124,0.00321
61.9,0.80485,14004.97556,0.00322
62.05,0.80684,14012.09831,0.00323
62.2,0.80814,14012.51554,0.00323
62.35,0.81044,14023.84043,0.00324
62.5,0.81367,14006.7637,0.00325
62.65,0.81369,14032.57251,0.00325
62.8,0.81499,14041.69202,0.00326
62.95,0.81682,14045.08948,0.00327
63.1,0.81908,14033.7646,0.00328
63.25,0.82187,14031.08239,0.00329
63.4,0.82385,14054.3282,0.0033
63.55,0.82422,14067.05379,0.0033
63.7,0.82682,14052.59967,0.00331
63.85,0.82873,14070.9281,0.00331
64,0.83317,14082.67021,0.00333
64.15,0.83302,14072.86525,0.00333
64.3,0.83354,14067.85846,0.00333
64.45,0.83494,14093.10102,0.00334
64.6,0.84057,14096.85612,0.00336
64.75,0.83833,14098.07801,0.00335
64.9,0.84257,14113.15799,0.00337
65.05,0.84487,14123.91663,0.00338
65.2,0.84355,14115.03553,0.00337
65.35,0.84724,14138.54957,0.00339
65.5,0.84994,14137.11905,0.0034
65.65,0.85133,14165.99751,0.00341
65.79999,0.85181,14134.40704,0.00341
65.95,0.85401,14143.52655,0.00342
66.1,0.8569,14165.52067,0.00343
66.25,0.85962,14178.06745,0.00344
66.4,0.85953,14158.1893,0.00344
66.54999,0.8623,14162.0338,0.00345
66.7,0.86414,14160.93111,0.00346
66.85,0.86623,14167.60683,0.00346
67,0.86821,14174.66998,0.00347
67.15,0.87059,14197.49856,0.00348
67.29999,0.86952,14180.0642,0.00348
67.45,0.87424,14202.98219,0.0035
67.6,0.8758,14200.65761,0.0035
67.75,0.87584,14211.56526,0.0035
67.9,0.8804,14220.50595,0.00352
68.04999,0.88064,14184.59415,0.00352
68.2,0.88125,14214.09845,0.00352
68.35,0.88455,14220.74437,0.00354
68.5,0.88806,14243.75176,0.00355
68.65,0.88858,14216.51244,0.00355
68.79999,0.89073,14221.102,0.00356
68.95,0.89273,14254.21238,0.00357
69.1,0.89319,14240.92054,0.00357
69.25,0.8985,14275.52104,0.00359
69.4,0.89854,14264.97102,0.00359
69.54999,0.90061,14265.62667,0.0036
69.7,0.90307,14282.49478,0.00361
69.85,0.90491,14279.33574,0.00362
70,0.90348,14276.2959,0.00361
70.15,0.90599,14292.50836,0.00362
70.29999,0.90963,14266.52074,0.00364
70.45,0.91265,14318.40658,0.00365
70.6,0.91345,14319.27085,0.00365
70.75,0.91555,14308.27379,0.00366
70.9,0.91656,14292.62757,0.00367
71.04999,0.91867,14294.71374,0.00367
71.2,0.92104,14337.09264,0.00368
71.35,0.92489,14342.63587,0.0037
71.5,0.92458,14342.93389,0.0037
71.65,0.92486,14330.50632,0.0037
71.79999,0.92662,14329.58245,0.00371
71.95,0.92985,14346.98701,0.00372
72.1,0.93132,14355.59988,0.00373
72.25,0.93498,14354.6164,0.00374
72.4,0.93496,14351.12953,0.00374
72.54999,0.93874,14381.70671,0.00375
72.7,0.93832,14383.13723,0.00375
72.85,0.94256,14380.72324,0.00377
73,0.94526,14392.58456,0.00378
73.15,0.9425,14375.18001,0.00377
73.29999,0.94711,14398.33641,0.00379
73.45,0.95047,14404.17767,0.0038
73.6,0.95164,14402.47893,0.00381
73.75,0.95221,14397.77017,0.00381
73.9,0.95713,14430.46331,0.00383
74.04999,0.95745,14436.7218,0.00383
74.2,0.95739,14420.92657,0.00383
74.35,0.96103,14427.00624,0.00384
74.5,0.96185,14426.82743,0.00385
74.65,0.96472,14433.89058,0.00386
74.79999,0.96481,14449.86463,0.00386
74.95,0.9671,14440.23848,0.00387
75.1,0.96838,14440.65571,0.00387
75.25,0.97049,14443.0697,0.00388
75.4,0.9737,14466.1665,0.00389
75.54999,0.97484,14487.14733,0.0039
75.7,0.97673,14475.2562,0.00391
75.85,0.98094,14497.63775,0.00392
76,0.98073,14472.48459,0.00392
76.15,0.98201,14468.69969,0.00393
76.29999,0.98669,14504.79031,0.00395
76.45,0.98669,14495.55159,0.00395
76.6,0.98971,14484.58433,0.00396
76.75,0.99052,14494.5085,0.00396
76.9,0.99232,14521.24119,0.00397
77.04999,0.99335,14502.88296,0.00397
77.2,0.99462,14523.71478,0.00398
77.35,0.99982,14499.75371,0.004
77.5,1.00093,14533.13231,0.004
77.65,1.0001,14514.89329,0.004
77.79999,1.00546,14558.46429,0.00402
77.95,1.00714,14532.74488,0.00403
78.1,1.00577,14553.15948,0.00402
78.25,1.0088,14560.28223,0.00404
78.4,1.01114,14569.61036,0.00404
78.54999,1.01259,14539.65902,0.00405
78.7,1.01325,14540.10606,0.00405
78.85,1.01886,14558.43449,0.00408
79,1.01852,14574.58735,0.00407
79.15,1.02046,14573.60387,0.00408
79.29999,1.02281,14590.56139,0.00409
79.45,1.02528,14580.54781,0.0041
79.6,1.02654,14604.09164,0.00411
79.75,1.02737,14585.82282,0.00411
79.9,1.02873,14610.97598,0.00411
80.04999,1.03355,14610.08191,0.00413
80.2,1.03226,14588.83286,0.00413
80.35,1.03532,14630.28789,0.00414
80.5,1.03911,14641.19554,0.00416
80.65,1.04041,14622.7181,0.00416
80.79999,1.03973,14644.5334,0.00416
80.95,1.04041,14630.34749,0.00416
81.1,1.04519,14646.26193,0.00418
81.25,1.04636,14647.30501,0.00419
81.4,1.04771,14636.00993,0.00419
81.54999,1.04713,14635.77151,0.00419
81.7,1.05292,14654.15955,0.00421
81.85,1.0543,14669.77596,0.00422
82,1.05487,14636.42716,0.00422
82.15,1.05815,14680.74322,0.00423
82.29999,1.06,14660.44784,0.00424
82.45,1.06089,14691.14423,0.00424
82.6,1.06432,14678.71666,0.00426
82.75,1.06444,14692.45553,0.00426
82.9,1.06876,14681.8161,0.00428
83.04999,1.06865,14719.48624,0.00427
83.2,1.07191,14686.13744,0.00429
83.35,1.07312,14699.8167,0.00429
83.5,1.07574,14705.35994,0.0043
83.65,1.07505,14744.37118,0.0043
83.79999,1.07938,14733.85096,0.00432
83.95,1.08059,14714.47945,0.00432
84.1,1.08377,14728.51634,0.00434
84.25,1.08254,14718.11533,0.00433
84.4,1.08669,14707.86333,0.00435
84.54999,1.08803,14727.65207,0.00435
84.7,1.08958,14740.55648,0.00436
84.85,1.09184,14740.19885,0.00437
85,1.0938,14737.60605,0.00438
85.15,1.09502,14759.18293,0.00438
85.29999,1.09743,14748.72231,0.00439
85.45,1.09882,14758.94451,0.0044
85.6,1.10235,14747.05338,0.00441
85.75,1.10415,14789.5515,0.00442
85.9,1.10351,14786.18383,0.00441
86.04999,1.10578,14784.12747,0.00442
86.2,1.11001,14772.65358,0.00444
86.35,1.10924,14798.93923,0.00444
86.5,1.11146,14764.69636,0.00445
86.65,1.1155,14813.66158,0.00446
86.79999,1.1148,14784.15728,0.00446
86.95,1.11768,14794.97552,0.00447
87.1,1.11897,14779.59752,0.00448
87.25,1.1222,14812.26087,0.00449
87.4,1.12463,14824.2116,0.0045
87.54999,1.12697,14828.20511,0.00451
87.7,1.1252,14804.39305,0.0045
87.85,1.12966,14830.26147,0.00452
88,1.13191,14822.45326,0.00453
88.15,1.13384,14867.66338,0.00454
88.29999,1.13629,14855.92127,0.00455
88.45,1.13596,14835.53648,0.00454
88.6,1.13984,14852.79202,0.00456
88.75,1.13983,14850.08001,0.00456
88.9,1.14372,14887.51173,0.00457
89.04999,1.14184,14874.42851,0.00457
89.2,1.14651,14872.22314,0.00459
89.35,1.1494,14881.40225,0.0046
89.5,1.14841,14846.0269,0.00459
89.65,1.15179,14875.41199,0.00461
89.79999,1.15398,14863.87849,0.00462
89.95,1.15455,14872.93839,0.00462
90.1,1.15762,14898.41938,0.00463
90.25,1.16024,14911.08537,0.00464
90.4,1.15871,14921.96321,0.00463
90.54999,1.16076,14896.54183,0.00464
90.7,1.16542,14898.38958,0.00466
90.85,1.16627,14933.91395,0.00467
91,1.1694,14897.58492,0.00468
91.14999,1.16955,14924.43681,0.00468
91.29999,1.17205,14929.86083,0.00469
91.45,1.17432,14925.89712,0.0047
91.6,1.17676,14957.15976,0.00471
91.75,1.17812,14937.93726,0.00471
91.89999,1.17934,14960.40821,0.00472
92.04999,1.184,14942.91425,0.00474
92.2,1.18275,14935.22525,0.00473
92.35,1.18454,14965.11698,0.00474
92.5,1.18687,14955.96766,0.00475
92.64999,1.1895,14968.96148,0.00476
92.79999,1.19191,14957.30877,0.00477
92.95,1.19164,14976.9783,0.00477
93.1,1.19437,14992.02847,0.00478
93.25,1.19526,14976.65048,0.00478
93.39999,1.19747,14980.793,0.00479
93.54999,1.19971,14963.35864,0.0048
93.7,1.20351,14992.3265,0.00481
93.85,1.20347,14982.99837,0.00481
94,1.20567,15003.77059,0.00482
94.14999,1.20819,14992.77353,0.00483
94.29999,1.20876,14991.70065,0.00484
94.45,1.21091,15009.93967,0.00484
94.6,1.21388,15024.00637,0.00486
94.75,1.21546,14996.02199,0.00486
94.89999,1.21692,15009.31382,0.00487
95.04999,1.22047,15005.37992,0.00488
95.2,1.2203,15025.04945,0.00488
95.35,1.2218,15043.88452,0.00489
95.5,1.22318,15054.37493,0.00489
95.64999,1.22749,15062.27255,0.00491
95.79999,1.22802,15033.00667,0.00491
95.95,1.23079,15045.07661,0.00492
96.1,1.23197,15048.8615,0.00493
96.25,1.23492,15076.19023,0.00494
96.39999,1.23697,15060.3056,0.00495
96.54999,1.23825,15055.98426,0.00495
96.7,1.23918,15065.31239,0.00496
96.85,1.24096,15058.96449,0.00496
97,1.24311,15070.34898,0.00497
97.14999,1.24505,15080.48177,0.00498
97.29999,1.24838,15068.0244,0.00499
97.45,1.24849,15062.74939,0.00499
97.6,1.25079,15113.86037,0.005
97.75,1.25165,15097.11146,0.00501
97.89999,1.25499,15097.20087,0.00502
98.04999,1.25757,15099.16782,0.00503
98.2,1.25792,15099.34664,0.00503
98.35,1.25877,15115.5889,0.00504
98.5,1.2633,15107.78069,0.00505
98.64999,1.26289,15128.28469,0.00505
98.79999,1.26415,15115.20147,0.00506
98.95,1.26843,15113.08551,0.00507
99.1,1.2694,15137.04658,0.00508
99.25,1.27095,15145.39123,0.00508
99.39999,1.27333,15133.70872,0.00509
99.54999,1.27248,15121.34075,0.00509
99.7,1.27574,15131.74176,0.0051
99.85,1.28108,15148.13304,0.00512
100,1.27996,15156.92472,0.00512
100.14999,1.28371,15162.49776,0.00513
100.29999,1.28423,15151.14307,0.00514
100.45,1.28648,15166.75949,0.00515
100.6,1.28877,15188.90262,0.00516
100.75,1.29077,15168.72644,0.00516
100.89999,1.29109,15165.5972,0.00516
101.04999,1.29361,15182.82294,0.00517
101.2,1.29472,15159.04069,0.00518
101.35,1.29872,15216.14194,0.00519
101.5,1.3015,15204.45943,0.00521
101.64999,1.3021,15185.83298,0.00521
101.79999,1.30236,15195.1611,0.00521
101.95,1.30464,15176.83268,0.00522
102.1,1.30733,15197.7241,0.00523
102.25,1.30851,15215.81411,0.00523
102.39999,1.30979,15221.23814,0.00524
102.54999,1.31411,15219.77782,0.00526
102.7,1.3143,15203.26734,0.00526
102.85,1.31728,15206.39658,0.00527
103,1.31883,15229.52318,0.00528
103.14999,1.3209,15227.61583,0.00528
103.29999,1.32125,15246.36149,0.00528
103.45,1.32495,15250.62323,0.0053
103.6,1.32793,15232.74183,0.00531
103.75,1.32836,15238.85131,0.00531
103.89999,1.33124,15253.03721,0.00532
104.04999,1.33339,15255.57041,0.00533
104.2,1.33389,15255.74923,0.00534
104.35,1.33477,15256.7029,0.00534
104.5,1.33555,15249.46094,0.00534
104.64999,1.34016,15269.96493,0.00536
104.79999,1.34092,15268.2364,0.00536
104.95,1.34171,15280.39575,0.00537
105.1,1.34422,15252.02394,0.00538
105.25,1.34562,15263.02099,0.00538
105.39999,1.34866,15278.548,0.00539
105.54999,1.34827,15267.64035,0.00539
105.7,1.35081,15288.29336,0.0054
105.85,1.35279,15295.1777,0.00541
106,1.35464,15289.36625,0.00542
106.14999,1.35704,15295.53533,0.00543
106.29999,1.36102,15293.56837,0.00544
106.45,1.36078,15280.15733,0.00544
106.6,1.36254,15316.87379,0.00545
106.75,1.36503,15322.71504,0.00546
106.89999,1.36737,15310.28748,0.00547
107.04999,1.36949,15317.20161,0.00548
107.2,1.37139,15328.5861,0.00549
107.35,1.37394,15323.63892,0.0055
107.5,1.37368,15305.54891,0.00549
107.64999,1.37578,15310.5855,0.0055
107.79999,1.37942,15323.3707,0.00552
107.95,1.37951,15331.29811,0.00552
108.1,1.38282,15339.37454,0.00553
108.25,1.38245,15341.72893,0.00553
108.39999,1.38556,15336.00688,0.00554
108.54999,1.3868,15335.14261,0.00555
108.7,1.389,15354.45452,0.00556
108.85,1.38938,15350.72923,0.00556
109,1.39255,15359.75933,0.00557
109.14999,1.39582,15359.99775,0.00558
109.29999,1.39764,15355.76582,0.00559
109.45,1.3996,15358.15001,0.0056
109.6,1.40219,15360.6832,0.00561
109.75,1.40195,15358.92487,0.00561
109.89999,1.40546,15354.30551,0.00562
110.04999,1.40655,15360.86202,0.00563
110.2,1.40866,15381.06799,0.00563
110.35,1.41232,15395.10489,0.00565
110.5,1.41095,15386.3728,0.00564
110.64999,1.41528,15392.39287,0.00566
110.79999,1.41589,15384.79328,0.00566
110.95,1.41691,15398.02551,0.00567
111.1,1.41907,15370.8756,0.00568
111.25,1.41815,15378.38578,0.00567
111.39999,1.42358,15405.35688,0.00569
111.54999,1.42571,15397.66788,0.0057
111.7,1.42857,15419.33417,0.00571
111.85,1.42964,15406.37016,0.00572
112,1.43116,15443.74228,0.00572
112.14999,1.43181,15428.81131,0.00573
112.29999,1.43504,15417.57584,0.00574
112.45,1.4351,15416.44335,0.00574
112.6,1.43808,15419.57259,0.00575
112.75,1.43915,15426.15891,0.00576
112.89999,1.44376,15412.09221,0.00578
113.04999,1.44274,15427.351,0.00577
113.2,1.44517,15430.86767,0.00578
113.35,1.44703,15425.32444,0.00579
113.5,1.45293,15440.97066,0.00581
113.64999,1.45107,15457.42154,0.0058
113.79999,1.45255,15456.08044,0.00581
113.95,1.4538,15450.14977,0.00582
114.1,1.45835,15464.45489,0.00583
114.25,1.45987,15463.94825,0.00584
114.39999,1.45944,15476.28641,0.00584
114.54999,1.46247,15449.52393,0.00585
114.7,1.46477,15468.4484,0.00586
114.85,1.4656,15471.36903,0.00586
115,1.46801,15468.95504,0.00587
115.14999,1.47249,15473.21677,0.00589
115.29999,1.47233,15482.30648,0.00589
115.45,1.47579,15483.73699,0.0059
115.6,1.47637,15504.98605,0.00591
115.75,1.47962,15517.62223,0.00592
115.89999,1.47868,15494.43603,0.00591
116.04999,1.48212,15495.50891,0.00593
116.2,1.48422,15500.21768,0.00594
116.35,1.48274,15498.81697,0.00593
116.5,1.48621,15493.57176,0.00594
116.64999,1.48648,15507.63845,0.00595
116.79999,1.49171,15493.12472,0.00597
116.95,1.49164,15494.70425,0.00597
117.1,1.49434,15501.29056,0.00598
117.25,1.4954,15519.08255,0.00598
117.39999,1.49898,15532.6128,0.006
117.54999,1.49927,15507.81727,0.006
117.7,1.50261,15534.99699,0.00601
117.85,1.50526,15510.85711,0.00602
118,1.50559,15512.1088,0.00602
118.14999,1.508,15532.583,0.00603
118.29999,1.50912,15537.44078,0.00604
118.45,1.51088,15518.4269,0.00604
118.6,1.51319,15534.69896,0.00605
118.75,1.51616,15547.93119,0.00606
118.89999,1.51696,15555.59039,0.00607
119.04999,1.52038,15567.00468,0.00608
119.2,1.5205,15567.2729,0.00608
119.35,1.5228,15564.08405,0.00609
119.5,1.52472,15563.27939,0.0061
119.64999,1.52539,15545.96424,0.0061
119.79999,1.52846,15578.47857,0.00611
119.95,1.52982,15578.15075,0.00612
120.1,1.53201,15564.08405,0.00613
120.25,1.53396,15597.96929,0.00614
120.39999,1.53476,15577.4951,0.00614
120.54999,1.53578,15567.39211,0.00614
120.7,1.54103,15591.56179,0.00616
120.85,1.53938,15593.58835,0.00616
121,1.54416,15598.47593,0.00618
121.14999,1.5459,15595.22748,0.00618
121.29999,1.54792,15597.31364,0.00619
121.45,1.54901,15595.85333,0.0062
121.6,1.54989,15600.02565,0.0062
121.75,1.55264,15589.80346,0.00621
121.89999,1.55361,15603.87015,0.00621
122.04999,1.5556,15613.31749,0.00622
122.2,1.55888,15627.47359,0.00624
122.35,1.56039,15633.07643,0.00624
122.5,1.56245,15596.65799,0.00625
122.64999,1.56401,15625.50664,0.00626
122.79999,1.5644,15633.25524,0.00626
122.95,1.56718,15628.30806,0.00627
123.1,1.56972,15628.8147,0.00628
123.25,1.57292,15642.58337,0.00629
123.39999,1.57462,15652.68636,0.0063
123.54999,1.57222,15634.26852,0.00629
123.7,1.57767,15643.80527,0.00631
123.85,1.57891,15639.90116,0.00632
124,1.58118,15627.08616,0.00632
124.14999,1.58088,15632.27177,0.00632
124.29999,1.58326,15675.0083,0.00633
124.45,1.5867,15641.80851,0.00635
124.6,1.58877,15644.13309,0.00636
124.75,1.59094,15664.48808,0.00636
124.89999,1.59335,15680.10449,0.00637
125.04999,1.59317,15643.20922,0.00637
125.2,1.59591,15655.60699,0.00638
125.35,1.59747,15650.18296,0.00639
125.5,1.59795,15674.71027,0.00639
125.64999,1.60207,15640.55681,0.00641
125.79999,1.60275,15645.504,0.00641
125.95,1.60598,15668.74981,0.00642
126.1,1.609,15677.30308,0.00644
126.25,1.60822,15662.46152,0.00643
126.39999,1.61099,15652.95458,0.00644
126.54999,1.61412,15673.07115,0.00646
126.7,1.61408,15653.78904,0.00646
126.85,1.61766,15659.03425,0.00647
127,1.6166,15669.8823,0.00647
127.14999,1.61889,15665.41195,0.00648
127.29999,1.62285,15634.05991,0.00649
127.45,1.62345,15667.43851,0.00649
127.6,1.62297,15651.34525,0.00649
127.75,1.62951,15695.5719,0.00652
127.89999,1.62877,15665.94839,0.00652
128.05,1.63195,15681.80323,0.00653
128.2,1.63243,15661.20982,0.00653
128.34999,1.63517,15676.97525,0.00654
128.5,1.63832,15691.99562,0.00655
128.64999,1.63768,15661.15022,0.00655
128.8,1.64259,15678.01833,0.00657
128.95,1.64459,15691.48898,0.00658
129.09999,1.64351,15690.62471,0.00657
129.25,1.64889,15669.9717,0.0066
129.39999,1.64912,15713.15527,0.0066
129.55,1.6515,15682.63769,0.00661
129.7,1.64971,15696.8832,0.0066
129.84999,1.65478,15712.02278,0.00662
130,1.65564,15706.24113,0.00662
130.14999,1.65851,15688.62796,0.00663
130.3,1.65903,15714.55598,0.00664
130.45,1.65968,15700.93632,0.00664
130.59999,1.66405,15695.51229,0.00666
130.75,1.66664,15691.45918,0.00667
130.89999,1.66675,15713.63211,0.00667
131.05,1.66882,15711.78436,0.00668
131.2,1.67073,15729.03991,0.00668
131.34998,1.67342,15707.40342,0.00669
131.5,1.67423,15717.26799,0.0067
131.65,1.67799,15733.95729,0.00671
131.8,1.67822,15736.22227,0.00671
131.95,1.68097,15738.99388,0.00672
132.09998,1.68107,15724.65897,0.00672
132.25,1.68422,15726.3875,0.00674
132.4,1.68598,15739.11309,0.00674
132.55,1.68821,15729.96378,0.00675
132.7,1.69014,15718.34087,0.00676
132.84998,1.68994,15737.80179,0.00676
133,1.69219,15722.96023,0.00677
133.15,1.69587,15749.54391,0.00678
133.3,1.69691,15733.77848,0.00679
133.45,1.69706,15749.99094,0.00679
133.59998,1.69949,15737.47396,0.0068
133.75,1.70565,15756.45804,0.00682
133.9,1.7078,15749.5141,0.00683
134.05,1.70699,15738.93428,0.00683
134.2,1.7097,15750.37837,0.00684
134.34998,1.71017,15748.76904,0.00684
134.5,1.71365,15755.20635,0.00685
134.65,1.71291,15769.9883,0.00685
134.8,1.71435,15754.5507,0.00686
134.95,1.7184,15767.06767,0.00687
135.09998,1.71997,15762.38871,0.00688
135.25,1.72247,15747.33853,0.00689
135.4,1.72404,15762.83574,0.0069
135.55,1.72328,15764.44507,0.00689
135.7,1.72749,15775.29311,0.00691
135.84998,1.7289,15765.87558,0.00692
136,1.73093,15771.38901,0.00692
136.15,1.73302,15788.0187,0.00693
136.3,1.73519,15780.41911,0.00694
136.45,1.7383,15768.58759,0.00695
136.59998,1.74073,15795.85671,0.00696
136.75,1.73943,15762.00128,0.00696
136.9,1.74368,15771.92545,0.00697
137.05,1.74454,15784.97887,0.00698
137.2,1.74653,15768.7068,0.00699
137.34998,1.74508,15771.77644,0.00698
137.5,1.74927,15824.61596,0.007
137.65,1.75247,15808.82072,0.00701
137.8,1.7516,15796.42296,0.00701
137.95,1.75586,15782.92251,0.00702
138.09998,1.75743,15808.37369,0.00703
138.25,1.75912,15822.85762,0.00704
138.4,1.7613,15806.85377,0.00705
138.55,1.76128,15802.50263,0.00705
138.7,1.76532,15804.17156,0.00706
138.84998,1.76564,15820.29462,0.00706
139,1.76747,15820.41383,0.00707
139.15,1.77139,15815.37724,0.00709
139.3,1.77097,15811.86056,0.00708
139.45,1.77534,15826.22528,0.0071
139.59998,1.77543,15834.03349,0.0071
139.75,1.77799,15825.06299,0.00711
139.9,1.77965,15839.96415,0.00712
140.05,1.78128,15838.41443,0.00713
140.2,1.78564,15843.42122,0.00714
140.34998,1.78585,15838.65285,0.00714
140.5,1.78497,15839.18929,0.00714
140.65,1.78856,15852.30231,0.00715
140.8,1.78859,15863.80601,0.00715
140.95,1.79149,15850.21615,0.00717
141.09998,1.79412,15863.50799,0.00718
141.25,1.7961,15845.53719,0.00718
141.4,1.79893,15846.40145,0.0072
141.55,1.79901,15871.67382,0.0072
141.7,1.80354,15869.55786,0.00721
141.84998,1.80407,15901.05891,0.00722
142,1.80609,15881.24037,0.00722
142.15,1.80699,15872.41888,0.00723
142.3,1.80947,15912.53281,0.00724
142.45,1.81132,15891.37316,0.00725
142.59998,1.81479,15885.68091,0.00726
142.75,1.81686,15878.40915,0.00727
142.9,1.81862,15878.17073,0.00727
143.05,1.81864,15903.02587,0.00727
143.2,1.82064,15893.54873,0.00728
143.34998,1.82183,15915.42363,0.00729
143.5,1.8228,15882.43246,0.00729
143.65,1.82835,15921.17548,0.00731
143.8,1.82877,15913.90371,0.00732
143.95,1.83133,15890.92612,0.00733
144.09998,1.83243,15924.66235,0.00733
144.25,1.83436,15899.74761,0.00734
144.4,1.83669,15906.0657,0.00735
144.55,1.83534,15917.27138,0.00734
144.7,1.8386,15930.83143,0.00735
144.84998,1.8412,15907.2578,0.00736
145,1.84419,15920.57943,0.00738
145.15,1.84515,15922.755,0.00738
145.3,1.84726,15907.70483,0.00739
145.45,1.84862,15938.60984,0.00739
145.59998,1.85116,15943.79544,0.0074
145.75,1.85299,15920.192,0.00741
145.9,1.85455,15944.15307,0.00742
146.05,1.85639,15968.47177,0.00743
146.2,1.86001,15960.15692,0.00744
146.34998,1.86093,15944.89813,0.00744
146.5,1.86213,15914.73818,0.00745
146.65,1.86301,15930.50361,0.00745
146.8,1.86566,15968.889,0.00746
146.95,1.86711,15955.00112,0.00747
147.09998,1.87074,15967.27967,0.00748
147.25,1.87169,15970.02149,0.00749
147.4,1.87503,15959.76949,0.0075
147.55,1.87576,15967.6373,0.0075
147.7,1.87737,15982.21064,0.00751
147.84998,1.87941,15978.54495,0.00752
148,1.88192,15978.06811,0.00753
148.15,1.88237,15978.72376,0.00753
148.3,1.88442,15986.65118,0.00754
148.45,1.88938,16020.80464,0.00756
148.59998,1.88777,15989.78043,0.00755
148.75,1.89076,15996.93298,0.00756
148.9,1.89385,15996.93298,0.00758
149.05,1.89336,15990.04865,0.00757
149.2,1.89703,16003.40009,0.00759
149.34998,1.90001,16000.44966,0.0076
149.5,1.90042,16016.98995,0.0076
149.65,1.90112,15993.47591,0.0076
149.8,1.90317,16026.16906,0.00761
149.95,1.90408,16025.96045,0.00762
150.09998,1.90816,16014.93359,0.00763
150.25,1.90847,16021.22188,0.00763
150.4,1.90977,15984.59482,0.00764
150.55,1.90972,16011.38711,0.00764
150.7,1.91316,16036.68928,0.00765
150.84998,1.91685,16031.8017,0.00767
151,1.91956,16042.0239,0.00768
151.15,1.91958,16008.34727,0.00768
151.3,1.92262,16019.76156,0.00769
151.45,1.92403,16059.07083,0.0077
151.59998,1.92551,16019.16552,0.0077
151.75,1.92626,16025.69222,0.00771
151.9,1.92986,16026.13926,0.00772
152.05,1.93082,16049.41487,0.00772
152.2,1.933,16060.0841,0.00773
152.34998,1.93466,16056.74624,0.00774
152.5,1.93773,16053.97463,0.00775
152.65,1.93647,16074.06139,0.00775
152.8,1.94214,16073.01831,0.00777
152.95,1.94185,16078.35293,0.00777
153.09998,1.94508,16073.70377,0.00778
153.25,1.94673,16057.28269,0.00779
153.4,1.9469,16074.77665,0.00779
153.55,1.95124,16086.28035,0.0078
153.7,1.95151,16077.28004,0.00781
153.84998,1.95411,16084.79023,0.00782
154,1.95501,16088.2175,0.00782
154.15,1.9576,16082.19743,0.00783
154.3,1.95786,16080.17087,0.00783
154.45,1.96061,16089.82682,0.00784
154.59998,1.96447,16124.99356,0.00786
154.75,1.96627,16100.04902,0.00787
154.9,1.9672,16101.83716,0.00787
155.05,1.96736,16086.28035,0.00787
155.2,1.97078,16116.58931,0.00788
155.34998,1.9722,16099.63179,0.00789
155.5,1.97484,16117.93041,0.0079
155.65,1.97469,16130.03016,0.0079
155.8,1.97771,16134.08327,0.00791
155.95,1.98115,16126.54328,0.00792
156.09998,1.98137,16110.21161,0.00793
156.25,1.98416,16124.75514,0.00794
156.4,1.98625,16148.06056,0.00794
156.55,1.98672,16134.85813,0.00795
156.7,1.98968,16128.65925,0.00796
156.84998,1.98973,16118.61587,0.00796
157,1.99287,16152.88854,0.00797
157.15,1.99603,16143.79883,0.00798
157.3,1.99605,16157.65691,0.00798
157.45,1.99969,16116.29128,0.008
157.59998,2.00093,16135.90121,0.008
157.75,2.00324,16154.55747,0.00801
157.9,2.00604,16137.62975,0.00802
158.05,2.00712,16146.74926,0.00803
158.2,2.00914,16144.27567,0.00804
158.34998,2.00961,16160.51793,0.00804
158.5,2.01343,16168.95199,0.00805
158.65,2.01534,16160.96497,0.00806
158.8,2.01522,16169.57784,0.00806
158.95,2.01747,16168.47515,0.00807
159.09998,2.01891,16183.1677,0.00808
159.25,2.02342,16177.20723,0.00809
159.4,2.02066,16142.1299,0.00808
159.55,2.02444,16168.47515,0.0081
159.7,2.0294,16170.14408,0.00812
159.84998,2.02887,16162.6935,0.00812
160,2.02873,16176.64099,0.00811
160.15,2.03354,16162.54449,0.00813
160.3,2.0361,16181.61798,0.00814
160.45,2.03621,16192.34681,0.00814
160.59998,2.03694,16201.79415,0.00815
160.75,2.04092,16196.96617,0.00816
160.9,2.04282,16193.4793,0.00817
161.05,2.04256,16171.93222,0.00817
161.2,2.0475,16192.67464,0.00819
161.34998,2.04741,16213.47666,0.00819
161.4,2.0498,16188.77053,0.0082